<?xml version="1.0"?>
<robot name="eezybotarm_mk2">
    <!-- Materials -->
    <material name="green">
        <color rgba="0 0.275 0 1"/>
    </material>
    <material name="blue">
        <color rgba="0 0 1 1"/>
    </material>
    <material name="red">
        <color rgba="1 0 0 1"/>
    </material>

    <!-- BASE LINK -->
    <link name="base_link">
        <visual>
            <origin xyz="0 0 0" rpy="0 0 0"/>
            <geometry>
                <mesh filename="package://eezybotarm/meshes/ebamk2/base_link.STL"/>
            </geometry>
            <material name="green"/>
        </visual>
        <collision>
            <origin xyz="0 0 0" rpy="0 0 0"/>
            <geometry>
                <mesh filename="package://eezybotarm/meshes/ebamk2/base_link.STL"/>
            </geometry>
        </collision>
        <inertial>
            <mass value="0.5"/>
            <inertia ixx="0.01" ixy="0.0" ixz="0.0" iyy="0.01" iyz="0.0" izz="0.01"/>
        </inertial>
    </link>

    <!-- JOINT 1 (Base Rotation) -->
    <joint name="joint_1" type="revolute">
        <origin xyz="0 0 0.05" rpy="0 0 0"/>
        <parent link="base_link"/>
        <child link="link_1"/>
        <axis xyz="0 0 1"/>
        <limit effort="10" velocity="1.0" lower="0" upper="3.14159"/>
        <dynamics damping="0.1" friction="0.1"/>
        <safety_controller k_position="100"
                          k_velocity="10"
                          soft_lower_limit="0.05"
                          soft_upper_limit="3.09159"/>
    </joint>

    <!-- LINK 1 -->
    <link name="link_1">
        <visual>
            <origin xyz="0 -0.04 0" rpy="0 0 0"/>
            <geometry>
                <mesh filename="package://eezybotarm/meshes/ebamk2/link_1.STL"/>
            </geometry>
            <material name="green"/>
        </visual>
        <collision>
            <origin xyz="0 -0.04 0" rpy="0 0 0"/>
            <geometry>
                <mesh filename="package://eezybotarm/meshes/ebamk2/link_1.STL"/>
            </geometry>
        </collision>
        <inertial>
            <mass value="0.3"/>
            <inertia ixx="0.01" ixy="0.0" ixz="0.0" iyy="0.01" iyz="0.0" izz="0.01"/>
        </inertial>
    </link>

    <!-- JOINT 2 (Shoulder) -->
    <joint name="joint_2" type="revolute">
        <origin xyz="0 -0.005 0.035" rpy="1.578 0 0"/>
        <parent link="link_1"/>
        <child link="link_2"/>
        <axis xyz="0 0 1"/>
        <limit effort="10" velocity="1.0" lower="0" upper="1.22173"/>  <!-- 0 to 70 degrees -->
        <dynamics damping="0.1" friction="0.1"/>
        <safety_controller k_position="100"
                          k_velocity="10"
                          soft_lower_limit="0.05"
                          soft_upper_limit="1.17173"/>
    </joint>

    <!-- LINK 2 -->
    <link name="link_2">
        <visual>
            <origin xyz="0 0 0.0075" rpy="3.14159 0 0"/>
            <geometry>
                <mesh filename="package://eezybotarm/meshes/ebamk2/link_2.STL"/>
            </geometry>
            <material name="blue"/>
        </visual>
        <collision>
            <origin xyz="0 0 0.0075" rpy="3.14159 0 0"/>
            <geometry>
                <mesh filename="package://eezybotarm/meshes/ebamk2/link_2.STL"/>
            </geometry>
        </collision>
        <inertial>
            <mass value="0.25"/>
            <inertia ixx="0.01" ixy="0.0" ixz="0.0" iyy="0.01" iyz="0.0" izz="0.01"/>
        </inertial>
    </link>

    <!-- JOINT 3 (Elbow) -->
    <joint name="joint_3" type="revolute">
        <origin xyz="-0.021 0.133 -0.0105" rpy="0 0 0"/>
        <parent link="link_2"/>
        <child link="link_3"/>
        <axis xyz="0 0 1"/>
        <limit effort="10" velocity="1.0" lower="1.48353" upper="2.96706"/>  <!-- 85 to 170 degrees -->
        <dynamics damping="0.1" friction="0.1"/>
        <safety_controller k_position="100"
                          k_velocity="10"
                          soft_lower_limit="1.53353"
                          soft_upper_limit="2.91706"/>
    </joint>

    <!-- LINK 3 -->
    <link name="link_3">
        <visual>
            <origin xyz="0 0 0.0335" rpy="3.14159 0 0.1309"/>
            <geometry>
                <mesh filename="package://eezybotarm/meshes/ebamk2/link_3.STL"/>
            </geometry>
            <material name="red"/>
        </visual>
        <collision>
            <origin xyz="0 0 0.0335" rpy="3.14159 0 0.1309"/>
            <geometry>
                <mesh filename="package://eezybotarm/meshes/ebamk2/link_3.STL"/>
            </geometry>
        </collision>
        <inertial>
            <mass value="0.2"/>
            <inertia ixx="0.01" ixy="0.0" ixz="0.0" iyy="0.01" iyz="0.0" izz="0.01"/>
        </inertial>
    </link>

    <!-- Added Gripper Joint -->
    <joint name="gripper_joint" type="revolute">
        <origin xyz="0 0.075 0" rpy="0 0 0"/>
        <parent link="link_3"/>
        <child link="gripper_link"/>
        <axis xyz="0 1 0"/>
        <limit effort="5" velocity="1.0" lower="0.349066" upper="1.74533"/>  <!-- 20 to 100 degrees -->
        <dynamics damping="0.1" friction="0.1"/>
        <safety_controller k_position="100"
                          k_velocity="10"
                          soft_lower_limit="0.399066"
                          soft_upper_limit="1.69533"/>
    </joint>

    <!-- Added Gripper Link -->
    <link name="gripper_link">
        <visual>
            <origin xyz="0 0 0" rpy="0 0 0"/>
            <geometry>
                <box size="0.02 0.02 0.02"/>
            </geometry>
            <material name="blue"/>
        </visual>
        <collision>
            <origin xyz="0 0 0" rpy="0 0 0"/>
            <geometry>
                <box size="0.02 0.02 0.02"/>
            </geometry>
        </collision>
        <inertial>
            <mass value="0.1"/>
            <inertia ixx="0.001" ixy="0.0" ixz="0.0" iyy="0.001" iyz="0.0" izz="0.001"/>
        </inertial>
    </link>

    <!-- Transmission elements for ros2_control -->
    <transmission name="joint_1_trans">
        <type>transmission_interface/SimpleTransmission</type>
        <joint name="joint_1">
            <hardwareInterface>hardware_interface/PositionJointInterface</hardwareInterface>
        </joint>
        <actuator name="joint_1_motor">
            <mechanicalReduction>1</mechanicalReduction>
        </actuator>
    </transmission>

    <transmission name="joint_2_trans">
        <type>transmission_interface/SimpleTransmission</type>
        <joint name="joint_2">
            <hardwareInterface>hardware_interface/PositionJointInterface</hardwareInterface>
        </joint>
        <actuator name="joint_2_motor">
            <mechanicalReduction>1</mechanicalReduction>
        </actuator>
    </transmission>

    <transmission name="joint_3_trans">
        <type>transmission_interface/SimpleTransmission</type>
        <joint name="joint_3">
            <hardwareInterface>hardware_interface/PositionJointInterface</hardwareInterface>
        </joint>
        <actuator name="joint_3_motor">
            <mechanicalReduction>1</mechanicalReduction>
        </actuator>
    </transmission>

    <transmission name="gripper_trans">
        <type>transmission_interface/SimpleTransmission</type>
        <joint name="gripper_joint">
            <hardwareInterface>hardware_interface/PositionJointInterface</hardwareInterface>
        </joint>
        <actuator name="gripper_motor">
            <mechanicalReduction>1</mechanicalReduction>
        </actuator>
    </transmission>
</robot>